Workbook
Name BID_INPUT_ASSET_BROKER_47c6c907: 'Bid Sheet'!$X$12:$X$330
Name BID_INPUT_BIDDER_MONTHLY_MAXIMUM_CAPACITY_5c7305b9: 'Bid Sheet'!$R$12:$R$330
Name BID_INPUT_CARRIER_NOTES_0142724f: 'Bid Sheet'!$Z$12:$Z$330
Name BID_INPUT_LINEHAUL_COST_DROP_TRAILER_af32aa1e: 'Bid Sheet'!$U$12:$U$330
Name BID_INPUT_LINEHAUL_COST_LIVE_LOAD_f8512053: 'Bid Sheet'!$W$12:$W$330
Name BID_INPUT_TRAFFIC_LIGHT_60b1fce8: 'Bid Sheet'!$B$12:$B$330
Name BID_INPUT_TRANSIT_TIME_IN_DAYS_2d28fb03: 'Bid Sheet'!$Y$12:$Y$330
Name BIDSHEET_VERSION: ReferenceData!$I$1:$I$1
Name CURRENCY_CAD: ReferenceData!$D$2:$D$2
Name CURRENCY_CODES: ReferenceData!$C$1:$C$2
Name CURRENCY_USD: ReferenceData!$D$1:$D$1
Name GLOBAL_INPUT_DETENTION_HR_AFTER_2_FREE_HOURS_3aa68460: 'Bid Sheet'!$E$3:$E$3
Name GLOBAL_INPUT_DETENTION_HR_AFTER_2_FREE_HOURS_CURRENCY_3aa68460: 'Bid Sheet'!$D$3:$D$3
Name GLOBAL_INPUT_LAYOVER_OCCURRENCE_712ff282: 'Bid Sheet'!$E$7:$E$7
Name GLOBAL_INPUT_LAYOVER_OCCURRENCE_CURRENCY_712ff282: 'Bid Sheet'!$D$7:$D$7
Name GLOBAL_INPUT_LUMPER_OCCURRENCE_c090d7ec: 'Bid Sheet'!$E$4:$E$4
Name GLOBAL_INPUT_LUMPER_OCCURRENCE_CURRENCY_c090d7ec: 'Bid Sheet'!$D$4:$D$4
Name GLOBAL_INPUT_STOP_OFF_CHARGE_STOP_LOCATION_FEE_68c87fb5: 'Bid Sheet'!$E$6:$E$6
Name GLOBAL_INPUT_STOP_OFF_CHARGE_STOP_LOCATION_FEE_CURRENCY_68c87fb5: 'Bid Sheet'!$D$6:$D$6
Name GLOBAL_INPUT_TONU_OCCURRENCE_CURRENCY_ed42e12d: 'Bid Sheet'!$D$5:$D$5
Name GLOBAL_INPUT_TONU_OCCURRENCE_ed42e12d: 'Bid Sheet'!$E$5:$E$5
Name OPTIONS_ASSET_BROKER_47c6c907: ReferenceData!$F$1:$F$2
Name OPTIONS_CURRENCY_REQUIRED_07aaceaf: ReferenceData!$E$1:$E$2
Name OPTIONS_TRANSIT_TIME_IN_DAYS_2d28fb03: ReferenceData!$G$1:$G$31
Name STATIC_AMBIENT_OR_REFRIGERATED_c797d6f0: 'Bid Sheet'!$N$12:$N$330
Name STATIC_CATEGORY_a3c686e7: 'Bid Sheet'!$E$12:$E$330
Name STATIC_COUNTRY_d523ebbd: 'Bid Sheet'!$D$12:$D$330
Name STATIC_CURRENCY_REQUIRED_07aaceaf: 'Bid Sheet'!$S$12:$S$330
Name STATIC_DESTINATION_CITY_10ed4177: 'Bid Sheet'!$J$12:$J$330
Name STATIC_DESTINATION_STATE_8db5bcf7: 'Bid Sheet'!$K$12:$K$330
Name STATIC_DESTINATION_ZIP_CODE_256e1963: 'Bid Sheet'!$I$12:$I$330
Name STATIC_DISTANCE_M_9e41120d: 'Bid Sheet'!$L$12:$L$330
Name STATIC_FORECASTED_VOLUME_2026_2e8fc2f2: 'Bid Sheet'!$P$12:$P$330
Name STATIC_FUEL_ESTIMATE_USD_52da20b1: 'Bid Sheet'!$O$12:$O$330
Name STATIC_KEY_dd65c1b4: 'Bid Sheet'!$C$12:$C$330
Name STATIC_LOADING_DROP_2e8f8eea: 'Bid Sheet'!$T$12:$T$330
Name STATIC_LOADING_LIVE_33af13c2: 'Bid Sheet'!$V$12:$V$330
Name STATIC_MONTHLY_FORECAST_VOLUME_710d40f7: 'Bid Sheet'!$Q$12:$Q$330
Name STATIC_ORIGIN_CITY_f11c71d7: 'Bid Sheet'!$G$12:$G$330
Name STATIC_ORIGIN_STATE_e60af2b7: 'Bid Sheet'!$H$12:$H$330
Name STATIC_ORIGIN_ZIP_f8693c5b: 'Bid Sheet'!$F$12:$F$330
Name STATIC_TRANSPORTATION_MODE_1d2d5bc7: 'Bid Sheet'!$M$12:$M$330
Name VALIDATION_LOT_IDENTIFIER_RANGE: ReferenceData!$A$1:$A$319

Sheet Overview
B2: Overview
B4: Overview
C6: Event Name: | D6: Flora Food Group - US & CA FTL
C7: Description: | D7: FTL Freight for US and Canada
C8: Welcome message: | D8: RFP Scope:
D9: Domestic services across the United States and Canada, covering full truckload
D10: (FTL), less than truckload (LTL), intermodal and select accessorial services.
D12: The RFP includes a diverse portfolio of established lanes across multiple
D13: regions, with consistent shipment activity for primary (Inbound), inter-DC (STO)
D14: and secondary (Customer Outbound) movement of goods.
D16: Our US network is currently consolidating from multiple distribution centers
D17: (DCs) to two (2) centralized DCs, with completion expected before mid‑year.
D18: Canada network will remain unchanged. At the same time, we are tracking toward
D19: full operational readiness of our new Hugoton factory in Kansas. As part of this
D20: transition, we will be reassessing our existing lanes and potentially
D21: introducing new lanes in the coming months to ensure future rates are aligned
D22: with the new network structure.
... D76: written consent from Flora Food Group is strictly prohibited.
B79: Details
C81: Event contact: | D81: Julio Luis-Martino <luis.julio-martino@florafg.com>
C82: Currency: | D82: USD
C83: Current round: | D83: Round 2
B86: Exchange Rates
C88: 1 USD = | D88: CAD 1.370000
B91: Schedule
C93: Round 1 | D93: 15:00 EST on February 18, 2026 – 17:00 EST on March 04, 2026
C94: Round 2 | D94: 10:24 EDT on March 18, 2026 – 17:00 EDT on March 24, 2026
B97: Validation Rules
C99: Must provide at least one type of pricing, Live Load or Drop Trailer.
B102: How to place bids using the Bid Sheet
C104: Instructions
C105: Step 1: Click on the "Bid Sheet" tab.
C106: Step 2: Ensure that all cells in the "Complete Bid" column either show "Yes" or are blank (meaning that you do not intend to bid on that lot).
C107: Step 3: Enter bids for each lot that you wish to be awarded.
C108: Step 4: Upload the completed file using your browser.
C110: Note:
C111: Yellow cells can be populated by you. Columns with an asterisk (*) are mandatory.
C112: If you wish to be awarded a lot, you must at a minimum complete all related mandatory cells.
C113: Do not make changes to any other areas within the spreadsheet. Doing so may prevent the processing of the completed Bid Sheet.
C114: Only the Excel .xlsx format can be accepted and processed.
...

Sheet ReferenceData
A1: 66031_36207_FTL_TC | C1: USD | D1: 1 | E1: USD | F1: Asset | G1: 0 | I1: 2
A2: 66031_72830_FTL_TC | C2: CAD | D2: 1.37 | E2: CAD | F2: Broker | G2: 1
A3: 18202_21903_FTL_TC | G3: 2
A4: 66031_35020_FTL_TC | G4: 3
A5: 66031_35217_FTL_TC | G5: 4
A6: 66031_35950_FTL_TC | G6: 5
A7: 66031_36010_FTL_TC | G7: 6
A8: 66031_36105_FTL_TC | G8: 7
A9: 66031_36801_FTL_TC | G9: 8
A10: 66031_72117_FTL_TC | G10: 9
A11: 66031_85043_FTL_TC | G11: 10
A12: 66031_85193_FTL_TC | G12: 11
A13: 66031_85226_FTL_TC | G13: 12
A14: 66031_85353_FTL_TC | G14: 13
... A31: 66031_95206_IM_TC | G31: 30
A32: 66031_95215_FTL_TC
A33: 66031_95215_IM_TC
A34: 66031_95358_FTL_TC
A35: 66031_95358_IM_TC
A36: 66031_95377_FTL_TC
A37: 66031_95377_IM_TC
A38: 66031_95691_FTL_TC
A39: 66031_95691_IM_TC
A40: 66031_95834_FTL_TC
A41: 66031_95834_IM_TC
A42: 66031_95835_FTL_TC
A43: 66031_95835_IM_TC
... A319: 18202_33411_FTL_TC

Sheet Bid Sheet
A1: Bid Sheet
A3: Detention: $/hr; after 2 free hours* | F3: Waiting time after free time
A4: Lumper: $/occurrence* | F4: 3rd party unloading charge
A5: TONU: $/occurrence* | F5: Truck ordered not used
A6: Stop-Off Charge: $/stop (location fee)* | F6: Additional Delivery Stop
A7: Layover: $/occurrence* | F7: Trailer held overnight
A9: Complete Bid | B9: Traffic Light | C9: KEY | D9: Country | E9: Category | F9: Origin Zip | G9: Origin City | H9: Origin State | I9: Destination Zip Code | J9: Destination City | K9: Destination State | L9: Distance (M) | M9: Transportation Mode | N9: Ambient or Refrigerated | O9: Fuel Estimate (USD) (USD) | P9: Forecasted Volume 2026 | Q9: Monthly Forecast Volume | R9: Bidder Monthly Maximum Capacity* | S9: Currency Required (Currency) | T9: Loading Drop | U9: Linehaul Cost - Drop Trailer | V9: Loading Live | W9: Linehaul Cost - Live Load | X9: Asset/Broker* | Y9: Transit Time in Days | Z9: Carrier Notes
U10: Currency Required | W10: Currency Required
B11: Green Light = 0-5% from Target. Yellow Light = 5-10% from Target. Red Light = 10%+ from Target. | R11: This number will be measured against the "Monthly Forecast Volume". | S11: You must provide your bid for each lane in the currency shown here. | T11: If this column says "Must", then you have to at least provide Drop Trailer pricing. | V11: If this column says "Must", then you have to at least provide Live Load pricing.
A12: =IF(AND(COUNTBLANK('Bid Sheet'!$R$12:$R$12)=1,COUNTBLANK('Bid Sheet'!$U$12:$U$12)=1,COUNTBLANK('Bid Sheet'!$W$12:$Z$12)=4),"",IF(OR(COUNTBLANK('Bid Sheet'!$R$12:$R$12)>0,COUNTBLANK('Bid Sheet'!$X$12:$X$12)>0, SUM(COUNTBLANK('Bid Sheet'!$D$3:$E$3), COUNTBLANK('Bid Sheet'!$D$4:$E$4), COUNTBLANK('Bid Sheet'!$D$5:$E$5), COUNTBLANK('Bid Sheet'!$D$6:$E$6), COUNTBLANK('Bid Sheet'!$D$7:$E$7))>0), "No", "Yes")) | C12: 66031_36207_FTL_TC | D12: US | E12: Customer Outbound | F12: 66031 | G12: NEW CENTURY | H12: KS | I12: 36207 | J12: ANNISTON | K12: AL | L12: 774 | M12: FTL_TC | N12: Refrigerated | O12: 330 | P12: 15 | Q12: 1.3 | S12: USD
A13: =IF(AND(COUNTBLANK('Bid Sheet'!$R$13:$R$13)=1,COUNTBLANK('Bid Sheet'!$U$13:$U$13)=1,COUNTBLANK('Bid Sheet'!$W$13:$Z$13)=4),"",IF(OR(COUNTBLANK('Bid Sheet'!$R$13:$R$13)>0,COUNTBLANK('Bid Sheet'!$X$13:$X$13)>0, SUM(COUNTBLANK('Bid Sheet'!$D$3:$E$3), COUNTBLANK('Bid Sheet'!$D$4:$E$4), COUNTBLANK('Bid Sheet'!$D$5:$E$5), COUNTBLANK('Bid Sheet'!$D$6:$E$6), COUNTBLANK('Bid Sheet'!$D$7:$E$7))>0), "No", "Yes")) | C13: 66031_72830_FTL_TC | D13: US | E13: Customer Outbound | F13: 66031 | G13: NEW CENTURY | H13: KS | I13: 72830 | J13: CLARKSVILLE | K13: AR | L13: 318 | M13: FTL_TC | N13: Refrigerated | O13: 132 | P13: 102 | Q13: 8.5 | S13: USD | T13: Must
A14: =IF(AND(COUNTBLANK('Bid Sheet'!$R$14:$R$14)=1,COUNTBLANK('Bid Sheet'!$U$14:$U$14)=1,COUNTBLANK('Bid Sheet'!$W$14:$Z$14)=4),"",IF(OR(COUNTBLANK('Bid Sheet'!$R$14:$R$14)>0,COUNTBLANK('Bid Sheet'!$X$14:$X$14)>0, SUM(COUNTBLANK('Bid Sheet'!$D$3:$E$3), COUNTBLANK('Bid Sheet'!$D$4:$E$4), COUNTBLANK('Bid Sheet'!$D$5:$E$5), COUNTBLANK('Bid Sheet'!$D$6:$E$6), COUNTBLANK('Bid Sheet'!$D$7:$E$7))>0), "No", "Yes")) | C14: 18202_21903_FTL_TC | D14: US | E14: Customer Outbound | F14: 18202 | G14: HAZLETON | H14: PA | I14: 21903 | J14: PERRYVILLE | K14: MD | L14: 147 | M14: FTL_TC | N14: Refrigerated | O14: 72 | P14: 8 | Q14: 0.7 | S14: USD
A15: =IF(AND(COUNTBLANK('Bid Sheet'!$R$15:$R$15)=1,COUNTBLANK('Bid Sheet'!$U$15:$U$15)=1,COUNTBLANK('Bid Sheet'!$W$15:$Z$15)=4),"",IF(OR(COUNTBLANK('Bid Sheet'!$R$15:$R$15)>0,COUNTBLANK('Bid Sheet'!$X$15:$X$15)>0, SUM(COUNTBLANK('Bid Sheet'!$D$3:$E$3), COUNTBLANK('Bid Sheet'!$D$4:$E$4), COUNTBLANK('Bid Sheet'!$D$5:$E$5), COUNTBLANK('Bid Sheet'!$D$6:$E$6), COUNTBLANK('Bid Sheet'!$D$7:$E$7))>0), "No", "Yes")) | C15: 66031_35020_FTL_TC | D15: US | E15: Customer Outbound | F15: 66031 | G15: NEW CENTURY | H15: KS | I15: 35020 | J15: BESSEMER | K15: AL | L15: 721 | M15: FTL_TC | N15: Refrigerated | O15: 308 | P15: 24 | Q15: 2 | S15: USD
A16: =IF(AND(COUNTBLANK('Bid Sheet'!$R$16:$R$16)=1,COUNTBLANK('Bid Sheet'!$U$16:$U$16)=1,COUNTBLANK('Bid Sheet'!$W$16:$Z$16)=4),"",IF(OR(COUNTBLANK('Bid Sheet'!$R$16:$R$16)>0,COUNTBLANK('Bid Sheet'!$X$16:$X$16)>0, SUM(COUNTBLANK('Bid Sheet'!$D$3:$E$3), COUNTBLANK('Bid Sheet'!$D$4:$E$4), COUNTBLANK('Bid Sheet'!$D$5:$E$5), COUNTBLANK('Bid Sheet'!$D$6:$E$6), COUNTBLANK('Bid Sheet'!$D$7:$E$7))>0), "No", "Yes")) | C16: 66031_35217_FTL_TC | D16: US | E16: Customer Outbound | F16: 66031 | G16: NEW CENTURY | H16: KS | I16: 35217 | J16: BIRMINGHAM | K16: AL | L16: 707 | M16: FTL_TC | N16: Refrigerated | O16: 305 | P16: 6 | Q16: 0.5 | S16: USD
A17: =IF(AND(COUNTBLANK('Bid Sheet'!$R$17:$R$17)=1,COUNTBLANK('Bid Sheet'!$U$17:$U$17)=1,COUNTBLANK('Bid Sheet'!$W$17:$Z$17)=4),"",IF(OR(COUNTBLANK('Bid Sheet'!$R$17:$R$17)>0,COUNTBLANK('Bid Sheet'!$X$17:$X$17)>0, SUM(COUNTBLANK('Bid Sheet'!$D$3:$E$3), COUNTBLANK('Bid Sheet'!$D$4:$E$4), COUNTBLANK('Bid Sheet'!$D$5:$E$5), COUNTBLANK('Bid Sheet'!$D$6:$E$6), COUNTBLANK('Bid Sheet'!$D$7:$E$7))>0), "No", "Yes")) | C17: 66031_35950_FTL_TC | D17: US | E17: Customer Outbound | F17: 66031 | G17: NEW CENTURY | H17: KS | I17: 35950 | J17: ALBERTVILLE | K17: AL | L17: 759 | M17: FTL_TC | N17: Refrigerated | O17: 317 | P17: 12 | Q17: 1 | S17: USD
A18: =IF(AND(COUNTBLANK('Bid Sheet'!$R$18:$R$18)=1,COUNTBLANK('Bid Sheet'!$U$18:$U$18)=1,COUNTBLANK('Bid Sheet'!$W$18:$Z$18)=4),"",IF(OR(COUNTBLANK('Bid Sheet'!$R$18:$R$18)>0,COUNTBLANK('Bid Sheet'!$X$18:$X$18)>0, SUM(COUNTBLANK('Bid Sheet'!$D$3:$E$3), COUNTBLANK('Bid Sheet'!$D$4:$E$4), COUNTBLANK('Bid Sheet'!$D$5:$E$5), COUNTBLANK('Bid Sheet'!$D$6:$E$6), COUNTBLANK('Bid Sheet'!$D$7:$E$7))>0), "No", "Yes")) | C18: 66031_36010_FTL_TC | D18: US | E18: Customer Outbound | F18: 66031 | G18: NEW CENTURY | H18: KS | I18: 36010 | J18: BRUNDIDGE | K18: AL | L18: 859 | M18: FTL_TC | N18: Refrigerated | O18: 369 | P18: 98 | Q18: 8.2 | S18: USD | T18: Must
A19: =IF(AND(COUNTBLANK('Bid Sheet'!$R$19:$R$19)=1,COUNTBLANK('Bid Sheet'!$U$19:$U$19)=1,COUNTBLANK('Bid Sheet'!$W$19:$Z$19)=4),"",IF(OR(COUNTBLANK('Bid Sheet'!$R$19:$R$19)>0,COUNTBLANK('Bid Sheet'!$X$19:$X$19)>0, SUM(COUNTBLANK('Bid Sheet'!$D$3:$E$3), COUNTBLANK('Bid Sheet'!$D$4:$E$4), COUNTBLANK('Bid Sheet'!$D$5:$E$5), COUNTBLANK('Bid Sheet'!$D$6:$E$6), COUNTBLANK('Bid Sheet'!$D$7:$E$7))>0), "No", "Yes")) | C19: 66031_36105_FTL_TC | D19: US | E19: Customer Outbound | F19: 66031 | G19: NEW CENTURY | H19: KS | I19: 36105 | J19: MONTGOMERY | K19: AL | L19: 796 | M19: FTL_TC | N19: Refrigerated | O19: 344 | P19: 54 | Q19: 4.5 | S19: USD
A20: =IF(AND(COUNTBLANK('Bid Sheet'!$R$20:$R$20)=1,COUNTBLANK('Bid Sheet'!$U$20:$U$20)=1,COUNTBLANK('Bid Sheet'!$W$20:$Z$20)=4),"",IF(OR(COUNTBLANK('Bid Sheet'!$R$20:$R$20)>0,COUNTBLANK('Bid Sheet'!$X$20:$X$20)>0, SUM(COUNTBLANK('Bid Sheet'!$D$3:$E$3), COUNTBLANK('Bid Sheet'!$D$4:$E$4), COUNTBLANK('Bid Sheet'!$D$5:$E$5), COUNTBLANK('Bid Sheet'!$D$6:$E$6), COUNTBLANK('Bid Sheet'!$D$7:$E$7))>0), "No", "Yes")) | C20: 66031_36801_FTL_TC | D20: US | E20: Customer Outbound | F20: 66031 | G20: NEW CENTURY | H20: KS | I20: 36801 | J20: OPELIKA | K20: AL | L20: 821 | M20: FTL_TC | N20: Refrigerated | O20: 353 | P20: 104 | Q20: 8.7 | S20: USD | T20: Must
A21: =IF(AND(COUNTBLANK('Bid Sheet'!$R$21:$R$21)=1,COUNTBLANK('Bid Sheet'!$U$21:$U$21)=1,COUNTBLANK('Bid Sheet'!$W$21:$Z$21)=4),"",IF(OR(COUNTBLANK('Bid Sheet'!$R$21:$R$21)>0,COUNTBLANK('Bid Sheet'!$X$21:$X$21)>0, SUM(COUNTBLANK('Bid Sheet'!$D$3:$E$3), COUNTBLANK('Bid Sheet'!$D$4:$E$4), COUNTBLANK('Bid Sheet'!$D$5:$E$5), COUNTBLANK('Bid Sheet'!$D$6:$E$6), COUNTBLANK('Bid Sheet'!$D$7:$E$7))>0), "No", "Yes")) | C21: 66031_72117_FTL_TC | D21: US | E21: Customer Outbound | F21: 66031 | G21: NEW CENTURY | H21: KS | I21: 72117 | J21: NORTH LITTLE ROCK | K21: AR | L21: 420 | M21: FTL_TC | N21: Refrigerated | O21: 170 | P21: 11 | Q21: 0.9 | S21: USD
A22: =IF(AND(COUNTBLANK('Bid Sheet'!$R$22:$R$22)=1,COUNTBLANK('Bid Sheet'!$U$22:$U$22)=1,COUNTBLANK('Bid Sheet'!$W$22:$Z$22)=4),"",IF(OR(COUNTBLANK('Bid Sheet'!$R$22:$R$22)>0,COUNTBLANK('Bid Sheet'!$X$22:$X$22)>0, SUM(COUNTBLANK('Bid Sheet'!$D$3:$E$3), COUNTBLANK('Bid Sheet'!$D$4:$E$4), COUNTBLANK('Bid Sheet'!$D$5:$E$5), COUNTBLANK('Bid Sheet'!$D$6:$E$6), COUNTBLANK('Bid Sheet'!$D$7:$E$7))>0), "No", "Yes")) | C22: 66031_85043_FTL_TC | D22: US | E22: Customer Outbound | F22: 66031 | G22: NEW CENTURY | H22: KS | I22: 85043 | J22: PHOENIX | K22: AZ | L22: 1179 | M22: FTL_TC | N22: Refrigerated | O22: 544 | P22: 38 | Q22: 3.2 | S22: USD
A23: =IF(AND(COUNTBLANK('Bid Sheet'!$R$23:$R$23)=1,COUNTBLANK('Bid Sheet'!$U$23:$U$23)=1,COUNTBLANK('Bid Sheet'!$W$23:$Z$23)=4),"",IF(OR(COUNTBLANK('Bid Sheet'!$R$23:$R$23)>0,COUNTBLANK('Bid Sheet'!$X$23:$X$23)>0, SUM(COUNTBLANK('Bid Sheet'!$D$3:$E$3), COUNTBLANK('Bid Sheet'!$D$4:$E$4), COUNTBLANK('Bid Sheet'!$D$5:$E$5), COUNTBLANK('Bid Sheet'!$D$6:$E$6), COUNTBLANK('Bid Sheet'!$D$7:$E$7))>0), "No", "Yes")) | C23: 66031_85193_FTL_TC | D23: US | E23: Customer Outbound | F23: 66031 | G23: NEW CENTURY | H23: KS | I23: 85193 | J23: CASA GRANDE | K23: AZ | L23: 1231 | M23: FTL_TC | N23: Refrigerated | O23: 543 | P23: 142 | Q23: 11.8 | S23: USD | T23: Must
A24: =IF(AND(COUNTBLANK('Bid Sheet'!$R$24:$R$24)=1,COUNTBLANK('Bid Sheet'!$U$24:$U$24)=1,COUNTBLANK('Bid Sheet'!$W$24:$Z$24)=4),"",IF(OR(COUNTBLANK('Bid Sheet'!$R$24:$R$24)>0,COUNTBLANK('Bid Sheet'!$X$24:$X$24)>0, SUM(COUNTBLANK('Bid Sheet'!$D$3:$E$3), COUNTBLANK('Bid Sheet'!$D$4:$E$4), COUNTBLANK('Bid Sheet'!$D$5:$E$5), COUNTBLANK('Bid Sheet'!$D$6:$E$6), COUNTBLANK('Bid Sheet'!$D$7:$E$7))>0), "No", "Yes")) | C24: 66031_85226_FTL_TC | D24: US | E24: Customer Outbound | F24: 66031 | G24: NEW CENTURY | H24: KS | I24: 85226 | J24: CHANDLER | K24: AZ | L24: 1171 | M24: FTL_TC | N24: Refrigerated | O24: 538 | P24: 22 | Q24: 1.8 | S24: USD
A25: =IF(AND(COUNTBLANK('Bid Sheet'!$R$25:$R$25)=1,COUNTBLANK('Bid Sheet'!$U$25:$U$25)=1,COUNTBLANK('Bid Sheet'!$W$25:$Z$25)=4),"",IF(OR(COUNTBLANK('Bid Sheet'!$R$25:$R$25)>0,COUNTBLANK('Bid Sheet'!$X$25:$X$25)>0, SUM(COUNTBLANK('Bid Sheet'!$D$3:$E$3), COUNTBLANK('Bid Sheet'!$D$4:$E$4), COUNTBLANK('Bid Sheet'!$D$5:$E$5), COUNTBLANK('Bid Sheet'!$D$6:$E$6), COUNTBLANK('Bid Sheet'!$D$7:$E$7))>0), "No", "Yes")) | C25: 66031_85353_FTL_TC | D25: US | E25: Customer Outbound | F25: 66031 | G25: NEW CENTURY | H25: KS | I25: 85353 | J25: TOLLESON | K25: AZ | L25: 1193 | M25: FTL_TC | N25: Refrigerated | O25: 549 | P25: 133 | Q25: 11.1 | S25: USD
A26: =IF(AND(COUNTBLANK('Bid Sheet'!$R$26:$R$26)=1,COUNTBLANK('Bid Sheet'!$U$26:$U$26)=1,COUNTBLANK('Bid Sheet'!$W$26:$Z$26)=4),"",IF(OR(COUNTBLANK('Bid Sheet'!$R$26:$R$26)>0,COUNTBLANK('Bid Sheet'!$X$26:$X$26)>0, SUM(COUNTBLANK('Bid Sheet'!$D$3:$E$3), COUNTBLANK('Bid Sheet'!$D$4:$E$4), COUNTBLANK('Bid Sheet'!$D$5:$E$5), COUNTBLANK('Bid Sheet'!$D$6:$E$6), COUNTBLANK('Bid Sheet'!$D$7:$E$7))>0), "No", "Yes")) | C26: 66031_90670_FTL_TC | D26: US | E26: Customer Outbound | F26: 66031 | G26: NEW CENTURY | H26: KS | I26: 90670 | J26: SANTA FE SPRINGS | K26: CA | L26: 1536 | M26: FTL_TC | N26: Refrigerated | O26: 769 | P26: 51 | Q26: 4.3 | S26: USD
A27: =IF(AND(COUNTBLANK('Bid Sheet'!$R$27:$R$27)=1,COUNTBLANK('Bid Sheet'!$U$27:$U$27)=1,COUNTBLANK('Bid Sheet'!$W$27:$Z$27)=4),"",IF(OR(COUNTBLANK('Bid Sheet'!$R$27:$R$27)>0,COUNTBLANK('Bid Sheet'!$X$27:$X$27)>0, SUM(COUNTBLANK('Bid Sheet'!$D$3:$E$3), COUNTBLANK('Bid Sheet'!$D$4:$E$4), COUNTBLANK('Bid Sheet'!$D$5:$E$5), COUNTBLANK('Bid Sheet'!$D$6:$E$6), COUNTBLANK('Bid Sheet'!$D$7:$E$7))>0), "No", "Yes")) | C27: 66031_90670_IM_TC | D27: US | E27: Customer Outbound | F27: 66031 | G27: NEW CENTURY | H27: KS | I27: 90670 | J27: SANTA FE SPRINGS | K27: CA | L27: 1536 | M27: IM_TC | N27: Refrigerated | O27: 313 | P27: 30 | Q27: 2.5 | S27: USD
A28: =IF(AND(COUNTBLANK('Bid Sheet'!$R$28:$R$28)=1,COUNTBLANK('Bid Sheet'!$U$28:$U$28)=1,COUNTBLANK('Bid Sheet'!$W$28:$Z$28)=4),"",IF(OR(COUNTBLANK('Bid Sheet'!$R$28:$R$28)>0,COUNTBLANK('Bid Sheet'!$X$28:$X$28)>0, SUM(COUNTBLANK('Bid Sheet'!$D$3:$E$3), COUNTBLANK('Bid Sheet'!$D$4:$E$4), COUNTBLANK('Bid Sheet'!$D$5:$E$5), COUNTBLANK('Bid Sheet'!$D$6:$E$6), COUNTBLANK('Bid Sheet'!$D$7:$E$7))>0), "No", "Yes")) | C28: 66031_91730_FTL_TC | D28: US | E28: Customer Outbound | F28: 66031 | G28: NEW CENTURY | H28: KS | I28: 91730 | J28: RANCHO CUCAMONGA | K28: CA | L28: 1507 | M28: FTL_TC | N28: Refrigerated | O28: 736 | P28: 63 | Q28: 5.3 | S28: USD
A29: =IF(AND(COUNTBLANK('Bid Sheet'!$R$29:$R$29)=1,COUNTBLANK('Bid Sheet'!$U$29:$U$29)=1,COUNTBLANK('Bid Sheet'!$W$29:$Z$29)=4),"",IF(OR(COUNTBLANK('Bid Sheet'!$R$29:$R$29)>0,COUNTBLANK('Bid Sheet'!$X$29:$X$29)>0, SUM(COUNTBLANK('Bid Sheet'!$D$3:$E$3), COUNTBLANK('Bid Sheet'!$D$4:$E$4), COUNTBLANK('Bid Sheet'!$D$5:$E$5), COUNTBLANK('Bid Sheet'!$D$6:$E$6), COUNTBLANK('Bid Sheet'!$D$7:$E$7))>0), "No", "Yes")) | C29: 66031_91752_FTL_TC | D29: US | E29: Customer Outbound | F29: 66031 | G29: NEW CENTURY | H29: KS | I29: 91752 | J29: MIRA LOMA | K29: CA | L29: 1505 | M29: FTL_TC | N29: Refrigerated | O29: 741 | P29: 56 | Q29: 4.7 | S29: USD
A30: =IF(AND(COUNTBLANK('Bid Sheet'!$R$30:$R$30)=1,COUNTBLANK('Bid Sheet'!$U$30:$U$30)=1,COUNTBLANK('Bid Sheet'!$W$30:$Z$30)=4),"",IF(OR(COUNTBLANK('Bid Sheet'!$R$30:$R$30)>0,COUNTBLANK('Bid Sheet'!$X$30:$X$30)>0, SUM(COUNTBLANK('Bid Sheet'!$D$3:$E$3), COUNTBLANK('Bid Sheet'!$D$4:$E$4), COUNTBLANK('Bid Sheet'!$D$5:$E$5), COUNTBLANK('Bid Sheet'!$D$6:$E$6), COUNTBLANK('Bid Sheet'!$D$7:$E$7))>0), "No", "Yes")) | C30: 66031_91752_IM_TC | D30: US | E30: Customer Outbound | F30: 66031 | G30: NEW CENTURY | H30: KS | I30: 91752 | J30: MIRA LOMA | K30: CA | L30: 1505 | M30: IM_TC | N30: Refrigerated | O30: 304 | P30: 34 | Q30: 2.8 | S30: USD
A31: =IF(AND(COUNTBLANK('Bid Sheet'!$R$31:$R$31)=1,COUNTBLANK('Bid Sheet'!$U$31:$U$31)=1,COUNTBLANK('Bid Sheet'!$W$31:$Z$31)=4),"",IF(OR(COUNTBLANK('Bid Sheet'!$R$31:$R$31)>0,COUNTBLANK('Bid Sheet'!$X$31:$X$31)>0, SUM(COUNTBLANK('Bid Sheet'!$D$3:$E$3), COUNTBLANK('Bid Sheet'!$D$4:$E$4), COUNTBLANK('Bid Sheet'!$D$5:$E$5), COUNTBLANK('Bid Sheet'!$D$6:$E$6), COUNTBLANK('Bid Sheet'!$D$7:$E$7))>0), "No", "Yes")) | C31: 66031_92324_FTL_TC | D31: US | E31: Customer Outbound | F31: 66031 | G31: NEW CENTURY | H31: KS | I31: 92324 | J31: COLTON | K31: CA | L31: 1496 | M31: FTL_TC | N31: Refrigerated | O31: 738 | P31: 69 | Q31: 5.8 | S31: USD | T31: Must
A32: =IF(AND(COUNTBLANK('Bid Sheet'!$R$32:$R$32)=1,COUNTBLANK('Bid Sheet'!$U$32:$U$32)=1,COUNTBLANK('Bid Sheet'!$W$32:$Z$32)=4),"",IF(OR(COUNTBLANK('Bid Sheet'!$R$32:$R$32)>0,COUNTBLANK('Bid Sheet'!$X$32:$X$32)>0, SUM(COUNTBLANK('Bid Sheet'!$D$3:$E$3), COUNTBLANK('Bid Sheet'!$D$4:$E$4), COUNTBLANK('Bid Sheet'!$D$5:$E$5), COUNTBLANK('Bid Sheet'!$D$6:$E$6), COUNTBLANK('Bid Sheet'!$D$7:$E$7))>0), "No", "Yes")) | C32: 66031_92324_IM_TC | D32: US | E32: Customer Outbound | F32: 66031 | G32: NEW CENTURY | H32: KS | I32: 92324 | J32: COLTON | K32: CA | L32: 1496 | M32: IM_TC | N32: Refrigerated | O32: 296 | P32: 20 | Q32: 1.7 | S32: USD | T32: Must
A33: =IF(AND(COUNTBLANK('Bid Sheet'!$R$33:$R$33)=1,COUNTBLANK('Bid Sheet'!$U$33:$U$33)=1,COUNTBLANK('Bid Sheet'!$W$33:$Z$33)=4),"",IF(OR(COUNTBLANK('Bid Sheet'!$R$33:$R$33)>0,COUNTBLANK('Bid Sheet'!$X$33:$X$33)>0, SUM(COUNTBLANK('Bid Sheet'!$D$3:$E$3), COUNTBLANK('Bid Sheet'!$D$4:$E$4), COUNTBLANK('Bid Sheet'!$D$5:$E$5), COUNTBLANK('Bid Sheet'!$D$6:$E$6), COUNTBLANK('Bid Sheet'!$D$7:$E$7))>0), "No", "Yes")) | C33: 66031_92507_FTL_TC | D33: US | E33: Customer Outbound | F33: 66031 | G33: NEW CENTURY | H33: KS | I33: 92507 | J33: RIVERSIDE | K33: CA | L33: 1506 | M33: FTL_TC | N33: Refrigerated | O33: 742 | P33: 83 | Q33: 6.9 | S33: USD | T33: Must
A34: =IF(AND(COUNTBLANK('Bid Sheet'!$R$34:$R$34)=1,COUNTBLANK('Bid Sheet'!$U$34:$U$34)=1,COUNTBLANK('Bid Sheet'!$W$34:$Z$34)=4),"",IF(OR(COUNTBLANK('Bid Sheet'!$R$34:$R$34)>0,COUNTBLANK('Bid Sheet'!$X$34:$X$34)>0, SUM(COUNTBLANK('Bid Sheet'!$D$3:$E$3), COUNTBLANK('Bid Sheet'!$D$4:$E$4), COUNTBLANK('Bid Sheet'!$D$5:$E$5), COUNTBLANK('Bid Sheet'!$D$6:$E$6), COUNTBLANK('Bid Sheet'!$D$7:$E$7))>0), "No", "Yes")) | C34: 66031_92507_IM_TC | D34: US | E34: Customer Outbound | F34: 66031 | G34: NEW CENTURY | H34: KS | I34: 92507 | J34: RIVERSIDE | K34: CA | L34: 1506 | M34: IM_TC | N34: Refrigerated | O34: 300 | P34: 21 | Q34: 1.8 | S34: USD | T34: Must
A35: =IF(AND(COUNTBLANK('Bid Sheet'!$R$35:$R$35)=1,COUNTBLANK('Bid Sheet'!$U$35:$U$35)=1,COUNTBLANK('Bid Sheet'!$W$35:$Z$35)=4),"",IF(OR(COUNTBLANK('Bid Sheet'!$R$35:$R$35)>0,COUNTBLANK('Bid Sheet'!$X$35:$X$35)>0, SUM(COUNTBLANK('Bid Sheet'!$D$3:$E$3), COUNTBLANK('Bid Sheet'!$D$4:$E$4), COUNTBLANK('Bid Sheet'!$D$5:$E$5), COUNTBLANK('Bid Sheet'!$D$6:$E$6), COUNTBLANK('Bid Sheet'!$D$7:$E$7))>0), "No", "Yes")) | C35: 66031_92555_FTL_TC | D35: US | E35: Customer Outbound | F35: 66031 | G35: NEW CENTURY | H35: KS | I35: 92555 | J35: MORENO VALLEY | K35: CA | L35: 1477 | M35: FTL_TC | N35: Refrigerated | O35: 702 | P35: 20 | Q35: 1.7 | S35: USD
A36: =IF(AND(COUNTBLANK('Bid Sheet'!$R$36:$R$36)=1,COUNTBLANK('Bid Sheet'!$U$36:$U$36)=1,COUNTBLANK('Bid Sheet'!$W$36:$Z$36)=4),"",IF(OR(COUNTBLANK('Bid Sheet'!$R$36:$R$36)>0,COUNTBLANK('Bid Sheet'!$X$36:$X$36)>0, SUM(COUNTBLANK('Bid Sheet'!$D$3:$E$3), COUNTBLANK('Bid Sheet'!$D$4:$E$4), COUNTBLANK('Bid Sheet'!$D$5:$E$5), COUNTBLANK('Bid Sheet'!$D$6:$E$6), COUNTBLANK('Bid Sheet'!$D$7:$E$7))>0), "No", "Yes")) | C36: 66031_92555_IM_TC | D36: US | E36: Customer Outbound | F36: 66031 | G36: NEW CENTURY | H36: KS | I36: 92555 | J36: MORENO VALLEY | K36: CA | L36: 1477 | M36: IM_TC | N36: Refrigerated | O36: 311 | P36: 6 | Q36: 0.5 | S36: USD
A37: =IF(AND(COUNTBLANK('Bid Sheet'!$R$37:$R$37)=1,COUNTBLANK('Bid Sheet'!$U$37:$U$37)=1,COUNTBLANK('Bid Sheet'!$W$37:$Z$37)=4),"",IF(OR(COUNTBLANK('Bid Sheet'!$R$37:$R$37)>0,COUNTBLANK('Bid Sheet'!$X$37:$X$37)>0, SUM(COUNTBLANK('Bid Sheet'!$D$3:$E$3), COUNTBLANK('Bid Sheet'!$D$4:$E$4), COUNTBLANK('Bid Sheet'!$D$5:$E$5), COUNTBLANK('Bid Sheet'!$D$6:$E$6), COUNTBLANK('Bid Sheet'!$D$7:$E$7))>0), "No", "Yes")) | C37: 66031_92801_FTL_TC | D37: US | E37: Customer Outbound | F37: 66031 | G37: NEW CENTURY | H37: KS | I37: 92801 | J37: ANAHEIM | K37: CA | L37: 1535 | M37: FTL_TC | N37: Refrigerated | O37: 766 | P37: 12 | Q37: 1 | S37: USD
A38: =IF(AND(COUNTBLANK('Bid Sheet'!$R$38:$R$38)=1,COUNTBLANK('Bid Sheet'!$U$38:$U$38)=1,COUNTBLANK('Bid Sheet'!$W$38:$Z$38)=4),"",IF(OR(COUNTBLANK('Bid Sheet'!$R$38:$R$38)>0,COUNTBLANK('Bid Sheet'!$X$38:$X$38)>0, SUM(COUNTBLANK('Bid Sheet'!$D$3:$E$3), COUNTBLANK('Bid Sheet'!$D$4:$E$4), COUNTBLANK('Bid Sheet'!$D$5:$E$5), COUNTBLANK('Bid Sheet'!$D$6:$E$6), COUNTBLANK('Bid Sheet'!$D$7:$E$7))>0), "No", "Yes")) | C38: 66031_92801_IM_TC | D38: US | E38: Customer Outbound | F38: 66031 | G38: NEW CENTURY | H38: KS | I38: 92801 | J38: ANAHEIM | K38: CA | L38: 1535 | M38: IM_TC | N38: Refrigerated | O38: 322 | P38: 3 | Q38: 0.3 | S38: USD
A39: =IF(AND(COUNTBLANK('Bid Sheet'!$R$39:$R$39)=1,COUNTBLANK('Bid Sheet'!$U$39:$U$39)=1,COUNTBLANK('Bid Sheet'!$W$39:$Z$39)=4),"",IF(OR(COUNTBLANK('Bid Sheet'!$R$39:$R$39)>0,COUNTBLANK('Bid Sheet'!$X$39:$X$39)>0, SUM(COUNTBLANK('Bid Sheet'!$D$3:$E$3), COUNTBLANK('Bid Sheet'!$D$4:$E$4), COUNTBLANK('Bid Sheet'!$D$5:$E$5), COUNTBLANK('Bid Sheet'!$D$6:$E$6), COUNTBLANK('Bid Sheet'!$D$7:$E$7))>0), "No", "Yes")) | C39: 66031_93263_FTL_TC | D39: US | E39: Customer Outbound | F39: 66031 | G39: NEW CENTURY | H39: KS | I39: 93263 | J39: SHAFTER | K39: CA | L39: 1573 | M39: FTL_TC | N39: Refrigerated | O39: 771 | P39: 94 | Q39: 7.8 | S39: USD | T39: Must
A40: =IF(AND(COUNTBLANK('Bid Sheet'!$R$40:$R$40)=1,COUNTBLANK('Bid Sheet'!$U$40:$U$40)=1,COUNTBLANK('Bid Sheet'!$W$40:$Z$40)=4),"",IF(OR(COUNTBLANK('Bid Sheet'!$R$40:$R$40)>0,COUNTBLANK('Bid Sheet'!$X$40:$X$40)>0, SUM(COUNTBLANK('Bid Sheet'!$D$3:$E$3), COUNTBLANK('Bid Sheet'!$D$4:$E$4), COUNTBLANK('Bid Sheet'!$D$5:$E$5), COUNTBLANK('Bid Sheet'!$D$6:$E$6), COUNTBLANK('Bid Sheet'!$D$7:$E$7))>0), "No", "Yes")) | C40: 66031_93263_IM_TC | D40: US | E40: Customer Outbound | F40: 66031 | G40: NEW CENTURY | H40: KS | I40: 93263 | J40: SHAFTER | K40: CA | L40: 1573 | M40: IM_TC | N40: Refrigerated | O40: 384 | P40: 23 | Q40: 1.9 | S40: USD | T40: Must
A41: =IF(AND(COUNTBLANK('Bid Sheet'!$R$41:$R$41)=1,COUNTBLANK('Bid Sheet'!$U$41:$U$41)=1,COUNTBLANK('Bid Sheet'!$W$41:$Z$41)=4),"",IF(OR(COUNTBLANK('Bid Sheet'!$R$41:$R$41)>0,COUNTBLANK('Bid Sheet'!$X$41:$X$41)>0, SUM(COUNTBLANK('Bid Sheet'!$D$3:$E$3), COUNTBLANK('Bid Sheet'!$D$4:$E$4), COUNTBLANK('Bid Sheet'!$D$5:$E$5), COUNTBLANK('Bid Sheet'!$D$6:$E$6), COUNTBLANK('Bid Sheet'!$D$7:$E$7))>0), "No", "Yes")) | C41: 66031_95206_FTL_TC | D41: US | E41: Customer Outbound | F41: 66031 | G41: NEW CENTURY | H41: KS | I41: 95206 | J41: STOCKTON | K41: CA | L41: 1474 | M41: FTL_TC | N41: Refrigerated | O41: 805 | P41: 75 | Q41: 6.3 | S41: USD
A42: =IF(AND(COUNTBLANK('Bid Sheet'!$R$42:$R$42)=1,COUNTBLANK('Bid Sheet'!$U$42:$U$42)=1,COUNTBLANK('Bid Sheet'!$W$42:$Z$42)=4),"",IF(OR(COUNTBLANK('Bid Sheet'!$R$42:$R$42)>0,COUNTBLANK('Bid Sheet'!$X$42:$X$42)>0, SUM(COUNTBLANK('Bid Sheet'!$D$3:$E$3), COUNTBLANK('Bid Sheet'!$D$4:$E$4), COUNTBLANK('Bid Sheet'!$D$5:$E$5), COUNTBLANK('Bid Sheet'!$D$6:$E$6), COUNTBLANK('Bid Sheet'!$D$7:$E$7))>0), "No", "Yes")) | C42: 66031_95206_IM_TC | D42: US | E42: Customer Outbound | F42: 66031 | G42: NEW CENTURY | H42: KS | I42: 95206 | J42: STOCKTON | K42: CA | L42: 1474 | M42: IM_TC | N42: Refrigerated | O42: 354 | P42: 22 | Q42: 1.8 | S42: USD
...
